[Mon Dec 17 17:30:44 2012] [info] [client 127.0.0.1] mod_wsgi (pid=5423, process='', application=''): Loading WSGI script '/home/brijesh/semis/semis.wsgi'.
[Mon Dec 17 17:30:44 2012] [error] [client 127.0.0.1] Traceback (most recent call last):
[Mon Dec 17 17:30:44 2012] [error] [client 127.0.0.1]   File "/usr/local/lib/python2.7/dist-packages/web/application.py", line 239, in process
[Mon Dec 17 17:30:44 2012] [error] [client 127.0.0.1]     return self.handle()
[Mon Dec 17 17:30:44 2012] [error] [client 127.0.0.1]   File "/usr/local/lib/python2.7/dist-packages/web/application.py", line 230, in handle
[Mon Dec 17 17:30:44 2012] [error] [client 127.0.0.1]     return self._delegate(fn, self.fvars, args)
[Mon Dec 17 17:30:44 2012] [error] [client 127.0.0.1]   File "/usr/local/lib/python2.7/dist-packages/web/application.py", line 462, in _delegate
[Mon Dec 17 17:30:44 2012] [error] [client 127.0.0.1]     return handle_class(cls)
[Mon Dec 17 17:30:44 2012] [error] [client 127.0.0.1]   File "/usr/local/lib/python2.7/dist-packages/web/application.py", line 438, in handle_class
[Mon Dec 17 17:30:44 2012] [error] [client 127.0.0.1]     return tocall(*args)
[Mon Dec 17 17:30:44 2012] [error] [client 127.0.0.1]   File "/home/brijesh/semis/semis.wsgi", line 34, in GET
[Mon Dec 17 17:30:44 2012] [error] [client 127.0.0.1]     sslc_district = db1.query('select distinct a.district_code,a.district_name from look_up as a,sslc_data as b where a.district_code=b.district_code')
[Mon Dec 17 17:30:44 2012] [error] [client 127.0.0.1]   File "/usr/local/lib/python2.7/dist-packages/web/db.py", line 643, in query
[Mon Dec 17 17:30:44 2012] [error] [client 127.0.0.1]     db_cursor = self._db_cursor()
[Mon Dec 17 17:30:44 2012] [error] [client 127.0.0.1]   File "/usr/local/lib/python2.7/dist-packages/web/db.py", line 566, in _db_cursor
[Mon Dec 17 17:30:44 2012] [error] [client 127.0.0.1]     return self.ctx.db.cursor()
[Mon Dec 17 17:30:44 2012] [error] [client 127.0.0.1]   File "/usr/local/lib/python2.7/dist-packages/web/db.py", line 507, in _getctx
[Mon Dec 17 17:30:44 2012] [error] [client 127.0.0.1]     self._load_context(self._ctx)
[Mon Dec 17 17:30:44 2012] [error] [client 127.0.0.1]   File "/usr/local/lib/python2.7/dist-packages/web/db.py", line 518, in _load_context
[Mon Dec 17 17:30:44 2012] [error] [client 127.0.0.1]     ctx.db = self._connect(self.keywords)
[Mon Dec 17 17:30:44 2012] [error] [client 127.0.0.1]   File "/usr/local/lib/python2.7/dist-packages/web/db.py", line 961, in _connect
[Mon Dec 17 17:30:44 2012] [error] [client 127.0.0.1]     conn = DB._connect(self, keywords)
[Mon Dec 17 17:30:44 2012] [error] [client 127.0.0.1]   File "/usr/local/lib/python2.7/dist-packages/web/db.py", line 546, in _connect
[Mon Dec 17 17:30:44 2012] [error] [client 127.0.0.1]     return self.db_module.connect(**keywords)
[Mon Dec 17 17:30:44 2012] [error] [client 127.0.0.1] OperationalError: FATAL:  Peer authentication failed for user "postgres"
[Mon Dec 17 17:30:44 2012] [error] [client 127.0.0.1] 
[Mon Dec 17 17:30:44 2012] [error] [client 127.0.0.1] 
[Mon Dec 17 17:30:46 2012] [info] [client 127.0.0.1] mod_wsgi (pid=5422, process='', application=''): Loading WSGI script '/home/brijesh/semis/semis.wsgi'.
[Mon Dec 17 17:30:47 2012] [error] [client 127.0.0.1] Traceback (most recent call last):
[Mon Dec 17 17:30:47 2012] [error] [client 127.0.0.1]   File "/usr/local/lib/python2.7/dist-packages/web/application.py", line 239, in process
[Mon Dec 17 17:30:47 2012] [error] [client 127.0.0.1]     return self.handle()
[Mon Dec 17 17:30:47 2012] [error] [client 127.0.0.1]   File "/usr/local/lib/python2.7/dist-packages/web/application.py", line 230, in handle
[Mon Dec 17 17:30:47 2012] [error] [client 127.0.0.1]     return self._delegate(fn, self.fvars, args)
[Mon Dec 17 17:30:47 2012] [error] [client 127.0.0.1]   File "/usr/local/lib/python2.7/dist-packages/web/application.py", line 462, in _delegate
[Mon Dec 17 17:30:47 2012] [error] [client 127.0.0.1]     return handle_class(cls)
[Mon Dec 17 17:30:47 2012] [error] [client 127.0.0.1]   File "/usr/local/lib/python2.7/dist-packages/web/application.py", line 438, in handle_class
[Mon Dec 17 17:30:47 2012] [error] [client 127.0.0.1]     return tocall(*args)
[Mon Dec 17 17:30:47 2012] [error] [client 127.0.0.1]   File "/home/brijesh/semis/semis.wsgi", line 34, in GET
[Mon Dec 17 17:30:47 2012] [error] [client 127.0.0.1]     sslc_district = db1.query('select distinct a.district_code,a.district_name from look_up as a,sslc_data as b where a.district_code=b.district_code')
[Mon Dec 17 17:30:47 2012] [error] [client 127.0.0.1]   File "/usr/local/lib/python2.7/dist-packages/web/db.py", line 643, in query
[Mon Dec 17 17:30:47 2012] [error] [client 127.0.0.1]     db_cursor = self._db_cursor()
[Mon Dec 17 17:30:47 2012] [error] [client 127.0.0.1]   File "/usr/local/lib/python2.7/dist-packages/web/db.py", line 566, in _db_cursor
[Mon Dec 17 17:30:47 2012] [error] [client 127.0.0.1]     return self.ctx.db.cursor()
[Mon Dec 17 17:30:47 2012] [error] [client 127.0.0.1]   File "/usr/local/lib/python2.7/dist-packages/web/db.py", line 507, in _getctx
[Mon Dec 17 17:30:47 2012] [error] [client 127.0.0.1]     self._load_context(self._ctx)
[Mon Dec 17 17:30:47 2012] [error] [client 127.0.0.1]   File "/usr/local/lib/python2.7/dist-packages/web/db.py", line 518, in _load_context
[Mon Dec 17 17:30:47 2012] [error] [client 127.0.0.1]     ctx.db = self._connect(self.keywords)
[Mon Dec 17 17:30:47 2012] [error] [client 127.0.0.1]   File "/usr/local/lib/python2.7/dist-packages/web/db.py", line 961, in _connect
[Mon Dec 17 17:30:47 2012] [error] [client 127.0.0.1]     conn = DB._connect(self, keywords)
[Mon Dec 17 17:30:47 2012] [error] [client 127.0.0.1]   File "/usr/local/lib/python2.7/dist-packages/web/db.py", line 546, in _connect
[Mon Dec 17 17:30:47 2012] [error] [client 127.0.0.1]     return self.db_module.connect(**keywords)
[Mon Dec 17 17:30:47 2012] [error] [client 127.0.0.1] OperationalError: FATAL:  Peer authentication failed for user "postgres"
[Mon Dec 17 17:30:47 2012] [error] [client 127.0.0.1] 
[Mon Dec 17 17:30:47 2012] [error] [client 127.0.0.1] 
[Mon Dec 17 17:34:50 2012] [info] [client 127.0.0.1] mod_wsgi (pid=5564, process='', application=''): Loading WSGI script '/home/brijesh/semis/semis.wsgi'.
[Mon Dec 17 17:34:50 2012] [error] [client 127.0.0.1] Traceback (most recent call last):
[Mon Dec 17 17:34:50 2012] [error] [client 127.0.0.1]   File "/usr/local/lib/python2.7/dist-packages/web/application.py", line 239, in process
[Mon Dec 17 17:34:50 2012] [error] [client 127.0.0.1]     return self.handle()
[Mon Dec 17 17:34:50 2012] [error] [client 127.0.0.1]   File "/usr/local/lib/python2.7/dist-packages/web/application.py", line 230, in handle
[Mon Dec 17 17:34:50 2012] [error] [client 127.0.0.1]     return self._delegate(fn, self.fvars, args)
[Mon Dec 17 17:34:50 2012] [error] [client 127.0.0.1]   File "/usr/local/lib/python2.7/dist-packages/web/application.py", line 462, in _delegate
[Mon Dec 17 17:34:50 2012] [error] [client 127.0.0.1]     return handle_class(cls)
[Mon Dec 17 17:34:50 2012] [error] [client 127.0.0.1]   File "/usr/local/lib/python2.7/dist-packages/web/application.py", line 438, in handle_class
[Mon Dec 17 17:34:50 2012] [error] [client 127.0.0.1]     return tocall(*args)
[Mon Dec 17 17:34:50 2012] [error] [client 127.0.0.1]   File "/home/brijesh/semis/semis.wsgi", line 34, in GET
[Mon Dec 17 17:34:50 2012] [error] [client 127.0.0.1]     sslc_district = db1.query('select distinct a.district_code,a.district_name from look_up as a,sslc_data as b where a.district_code=b.district_code')
[Mon Dec 17 17:34:50 2012] [error] [client 127.0.0.1]   File "/usr/local/lib/python2.7/dist-packages/web/db.py", line 643, in query
[Mon Dec 17 17:34:50 2012] [error] [client 127.0.0.1]     db_cursor = self._db_cursor()
[Mon Dec 17 17:34:50 2012] [error] [client 127.0.0.1]   File "/usr/local/lib/python2.7/dist-packages/web/db.py", line 566, in _db_cursor
[Mon Dec 17 17:34:50 2012] [error] [client 127.0.0.1]     return self.ctx.db.cursor()
[Mon Dec 17 17:34:50 2012] [error] [client 127.0.0.1]   File "/usr/local/lib/python2.7/dist-packages/web/db.py", line 507, in _getctx
[Mon Dec 17 17:34:50 2012] [error] [client 127.0.0.1]     self._load_context(self._ctx)
[Mon Dec 17 17:34:50 2012] [error] [client 127.0.0.1]   File "/usr/local/lib/python2.7/dist-packages/web/db.py", line 518, in _load_context
[Mon Dec 17 17:34:50 2012] [error] [client 127.0.0.1]     ctx.db = self._connect(self.keywords)
[Mon Dec 17 17:34:50 2012] [error] [client 127.0.0.1]   File "/usr/local/lib/python2.7/dist-packages/web/db.py", line 961, in _connect
[Mon Dec 17 17:34:50 2012] [error] [client 127.0.0.1]     conn = DB._connect(self, keywords)
[Mon Dec 17 17:34:50 2012] [error] [client 127.0.0.1]   File "/usr/local/lib/python2.7/dist-packages/web/db.py", line 546, in _connect
[Mon Dec 17 17:34:50 2012] [error] [client 127.0.0.1]     return self.db_module.connect(**keywords)
[Mon Dec 17 17:34:50 2012] [error] [client 127.0.0.1] OperationalError: FATAL:  Peer authentication failed for user "postgres"
[Mon Dec 17 17:34:50 2012] [error] [client 127.0.0.1] 
[Mon Dec 17 17:34:50 2012] [error] [client 127.0.0.1] 
